<?xml version="1.0" encoding="UTF-8"?>
<!-- Generated by org.testng.reporters.JUnitXMLReporter -->
<testsuite ignored="0" hostname="Mds-MacBook-Pro.local" failures="1" tests="1" name="Default test" time="0.218" errors="0" timestamp="2024-09-20T00:55:51 EDT">
  <testcase classname="database.Students_Details" name="testDB" time="0.183">
    <failure type="com.mysql.cj.jdbc.exceptions.CommunicationsException" message="Communications link failure

The last packet sent successfully to the server was 0 milliseconds ago. The driver has not received any packets from the server.">
      <![CDATA[com.mysql.cj.jdbc.exceptions.CommunicationsException: Communications link failure

The last packet sent successfully to the server was 0 milliseconds ago. The driver has not received any packets from the server.
at mysql.connector.j@9.0.0/com.mysql.cj.jdbc.exceptions.SQLError.createCommunicationsException(SQLError.java:165)
at mysql.connector.j@9.0.0/com.mysql.cj.jdbc.exceptions.SQLExceptionsMapping.translateException(SQLExceptionsMapping.java:55)
at mysql.connector.j@9.0.0/com.mysql.cj.jdbc.ConnectionImpl.createNewIO(ConnectionImpl.java:845)
at mysql.connector.j@9.0.0/com.mysql.cj.jdbc.ConnectionImpl.<init>(ConnectionImpl.java:420)
at mysql.connector.j@9.0.0/com.mysql.cj.jdbc.ConnectionImpl.getInstance(ConnectionImpl.java:238)
at mysql.connector.j@9.0.0/com.mysql.cj.jdbc.NonRegisteringDriver.connect(NonRegisteringDriver.java:180)
at java.sql/java.sql.DriverManager.getConnection(DriverManager.java:682)
at java.sql/java.sql.DriverManager.getConnection(DriverManager.java:230)
at database.Students_Details.testDB(Students_Details.java:21)
at java.base/jdk.internal.reflect.DirectMethodHandleAccessor.invoke(DirectMethodHandleAccessor.java:103)
at java.base/java.lang.reflect.Method.invoke(Method.java:580)
at org.testng.internal.MethodInvocationHelper.invokeMethod(MethodInvocationHelper.java:133)
at org.testng.internal.TestInvoker.invokeMethod(TestInvoker.java:598)
at org.testng.internal.TestInvoker.invokeTestMethod(TestInvoker.java:173)
at org.testng.internal.MethodRunner.runInSequence(MethodRunner.java:46)
at org.testng.internal.TestInvoker$MethodInvocationAgent.invoke(TestInvoker.java:824)
at org.testng.internal.TestInvoker.invokeTestMethods(TestInvoker.java:146)
at org.testng.internal.TestMethodWorker.invokeTestMethods(TestMethodWorker.java:146)
at org.testng.internal.TestMethodWorker.run(TestMethodWorker.java:128)
at java.base/java.util.ArrayList.forEach(ArrayList.java:1597)
at org.testng.TestRunner.privateRun(TestRunner.java:794)
at org.testng.TestRunner.run(TestRunner.java:596)
at org.testng.SuiteRunner.runTest(SuiteRunner.java:377)
at org.testng.SuiteRunner.runSequentially(SuiteRunner.java:371)
at org.testng.SuiteRunner.privateRun(SuiteRunner.java:332)
at org.testng.SuiteRunner.run(SuiteRunner.java:276)
at org.testng.SuiteRunnerWorker.runSuite(SuiteRunnerWorker.java:53)
at org.testng.SuiteRunnerWorker.run(SuiteRunnerWorker.java:96)
at org.testng.TestNG.runSuitesSequentially(TestNG.java:1212)
at org.testng.TestNG.runSuitesLocally(TestNG.java:1134)
at org.testng.TestNG.runSuites(TestNG.java:1063)
at org.testng.TestNG.run(TestNG.java:1031)
at org.testng.remote.AbstractRemoteTestNG.run(AbstractRemoteTestNG.java:115)
at org.testng.remote.RemoteTestNG.initAndRun(RemoteTestNG.java:293)
at org.testng.remote.RemoteTestNG.main(RemoteTestNG.java:91)
Caused by: com.mysql.cj.exceptions.CJCommunicationsException: Communications link failure

The last packet sent successfully to the server was 0 milliseconds ago. The driver has not received any packets from the server.
at java.base/jdk.internal.reflect.DirectConstructorHandleAccessor.newInstance(DirectConstructorHandleAccessor.java:62)
at java.base/java.lang.reflect.Constructor.newInstanceWithCaller(Constructor.java:502)
at java.base/java.lang.reflect.Constructor.newInstance(Constructor.java:486)
at mysql.connector.j@9.0.0/com.mysql.cj.exceptions.ExceptionFactory.createException(ExceptionFactory.java:52)
at mysql.connector.j@9.0.0/com.mysql.cj.exceptions.ExceptionFactory.createException(ExceptionFactory.java:95)
at mysql.connector.j@9.0.0/com.mysql.cj.exceptions.ExceptionFactory.createException(ExceptionFactory.java:140)
at mysql.connector.j@9.0.0/com.mysql.cj.exceptions.ExceptionFactory.createCommunicationsException(ExceptionFactory.java:156)
at mysql.connector.j@9.0.0/com.mysql.cj.protocol.a.NativeSocketConnection.connect(NativeSocketConnection.java:79)
at mysql.connector.j@9.0.0/com.mysql.cj.NativeSession.connect(NativeSession.java:140)
at mysql.connector.j@9.0.0/com.mysql.cj.jdbc.ConnectionImpl.connectOneTryOnly(ConnectionImpl.java:969)
at mysql.connector.j@9.0.0/com.mysql.cj.jdbc.ConnectionImpl.createNewIO(ConnectionImpl.java:833)
... 32 more
Caused by: java.net.ConnectException: Connection refused
at java.base/sun.nio.ch.Net.connect0(Native Method)
at java.base/sun.nio.ch.Net.connect(Net.java:589)
at java.base/sun.nio.ch.Net.connect(Net.java:578)
at java.base/sun.nio.ch.NioSocketImpl.connect(NioSocketImpl.java:583)
at java.base/java.net.SocksSocketImpl.connect(SocksSocketImpl.java:327)
at java.base/java.net.Socket.connect(Socket.java:752)
at mysql.connector.j@9.0.0/com.mysql.cj.protocol.StandardSocketFactory.connect(StandardSocketFactory.java:144)
at mysql.connector.j@9.0.0/com.mysql.cj.protocol.a.NativeSocketConnection.connect(NativeSocketConnection.java:53)
... 35 more
]]>
    </failure>
  </testcase> <!-- testDB -->
</testsuite> <!-- Default test -->
